Traceback (most recent call last):
  File "C:\Users\Juli\Desktop\Juliana\Programacion\docs\Pep8\.venv\lib\site-packages\jupyter_cache\executors\utils.py", line 58, in single_nb_execution
    executenb(
  File "C:\Users\Juli\Desktop\Juliana\Programacion\docs\Pep8\.venv\lib\site-packages\nbclient\client.py", line 1314, in execute
    return NotebookClient(nb=nb, resources=resources, km=km, **kwargs).execute()
  File "C:\Users\Juli\Desktop\Juliana\Programacion\docs\Pep8\.venv\lib\site-packages\jupyter_core\utils\__init__.py", line 165, in wrapped
    return loop.run_until_complete(inner)
  File "C:\Python310\lib\asyncio\base_events.py", line 649, in run_until_complete
    return future.result()
  File "C:\Users\Juli\Desktop\Juliana\Programacion\docs\Pep8\.venv\lib\site-packages\nbclient\client.py", line 709, in async_execute
    await self.async_execute_cell(
  File "C:\Users\Juli\Desktop\Juliana\Programacion\docs\Pep8\.venv\lib\site-packages\nbclient\client.py", line 1062, in async_execute_cell
    await self._check_raise_for_error(cell, cell_index, exec_reply)
  File "C:\Users\Juli\Desktop\Juliana\Programacion\docs\Pep8\.venv\lib\site-packages\nbclient\client.py", line 918, in _check_raise_for_error
    raise CellExecutionError.from_cell_and_msg(cell, exec_reply_content)
nbclient.exceptions.CellExecutionError: An error occurred while executing the following cell:
------------------
!python mixed_indentation.py
  File "./mixed_indentation.py", line 4
    print("World")  # Indented with a tab.
------------------


[1;36m  Cell [1;32mIn[9], line 2[1;36m[0m
[1;33m    File "./mixed_indentation.py", line 4[0m
[1;37m    ^[0m
[1;31mIndentationError[0m[1;31m:[0m unexpected indent


